[2023-06-30T04:25:23.417+0000] {taskinstance.py:1103} INFO - Dependencies all met for dep_context=non-requeueable deps ti=<TaskInstance: order-letter_NER.read_order_from_mail manual__2023-06-30T04:25:16.047807+00:00 [queued]>
[2023-06-30T04:25:23.427+0000] {taskinstance.py:1103} INFO - Dependencies all met for dep_context=requeueable deps ti=<TaskInstance: order-letter_NER.read_order_from_mail manual__2023-06-30T04:25:16.047807+00:00 [queued]>
[2023-06-30T04:25:23.428+0000] {taskinstance.py:1308} INFO - Starting attempt 1 of 6
[2023-06-30T04:25:23.454+0000] {taskinstance.py:1327} INFO - Executing <Task(PythonOperator): read_order_from_mail> on 2023-06-30 04:25:16.047807+00:00
[2023-06-30T04:25:23.460+0000] {standard_task_runner.py:57} INFO - Started process 402 to run task
[2023-06-30T04:25:23.467+0000] {standard_task_runner.py:84} INFO - Running: ['***', 'tasks', 'run', 'order-letter_NER', 'read_order_from_mail', 'manual__2023-06-30T04:25:16.047807+00:00', '--job-id', '48', '--raw', '--subdir', 'DAGS_FOLDER/order-letter-extraction.py', '--cfg-path', '/tmp/tmpmktspomh']
[2023-06-30T04:25:23.471+0000] {standard_task_runner.py:85} INFO - Job 48: Subtask read_order_from_mail
[2023-06-30T04:25:23.557+0000] {task_command.py:410} INFO - Running <TaskInstance: order-letter_NER.read_order_from_mail manual__2023-06-30T04:25:16.047807+00:00 [running]> on host f7b244b51c6e
[2023-06-30T04:25:23.731+0000] {taskinstance.py:1545} INFO - Exporting env vars: AIRFLOW_CTX_DAG_OWNER='Abin Jilson' AIRFLOW_CTX_DAG_ID='order-letter_NER' AIRFLOW_CTX_TASK_ID='read_order_from_mail' AIRFLOW_CTX_EXECUTION_DATE='2023-06-30T04:25:16.047807+00:00' AIRFLOW_CTX_TRY_NUMBER='1' AIRFLOW_CTX_DAG_RUN_ID='manual__2023-06-30T04:25:16.047807+00:00'
[2023-06-30T04:29:53.971+0000] {logging_mixin.py:149} INFO - An error occurred: [Errno -3] Temporary failure in name resolution
[2023-06-30T04:31:03.519+0000] {local_task_job_runner.py:291} WARNING - State of this instance has been externally set to None. Terminating instance.
[2023-06-30T04:31:03.537+0000] {process_utils.py:131} INFO - Sending Signals.SIGTERM to group 402. PIDs of all processes in the group: [402]
[2023-06-30T04:31:03.558+0000] {process_utils.py:86} INFO - Sending the signal Signals.SIGTERM to group 402
[2023-06-30T04:31:03.559+0000] {taskinstance.py:1517} ERROR - Received SIGTERM. Terminating subprocesses.
[2023-06-30T04:31:03.601+0000] {taskinstance.py:1824} ERROR - Task failed with exception
Traceback (most recent call last):
  File "/home/airflow/.local/lib/python3.8/site-packages/airflow/operators/python.py", line 181, in execute
    return_value = self.execute_callable()
  File "/home/airflow/.local/lib/python3.8/site-packages/airflow/operators/python.py", line 198, in execute_callable
    return self.python_callable(*self.op_args, **self.op_kwargs)
  File "/opt/airflow/dags/order-letter-extraction.py", line 67, in read_order_from_mail
    time.sleep(10)
  File "/home/airflow/.local/lib/python3.8/site-packages/airflow/models/taskinstance.py", line 1519, in signal_handler
    raise AirflowException("Task received SIGTERM signal")
airflow.exceptions.AirflowException: Task received SIGTERM signal
[2023-06-30T04:31:03.634+0000] {taskinstance.py:1345} INFO - Marking task as UP_FOR_RETRY. dag_id=order-letter_NER, task_id=read_order_from_mail, execution_date=20230630T042516, start_date=20230630T042523, end_date=20230630T043103
[2023-06-30T04:31:03.675+0000] {standard_task_runner.py:104} ERROR - Failed to execute job 48 for task read_order_from_mail (Task received SIGTERM signal; 402)
[2023-06-30T04:31:03.710+0000] {process_utils.py:79} INFO - Process psutil.Process(pid=402, status='terminated', exitcode=1, started='04:25:23') (402) terminated with exit code 1
