[2023-06-30T05:20:12.337+0000] {taskinstance.py:1103} INFO - Dependencies all met for dep_context=non-requeueable deps ti=<TaskInstance: order-letter_NER.check_confidence_task manual__2023-06-30T05:04:47.216784+00:00 [queued]>
[2023-06-30T05:20:12.350+0000] {taskinstance.py:1103} INFO - Dependencies all met for dep_context=requeueable deps ti=<TaskInstance: order-letter_NER.check_confidence_task manual__2023-06-30T05:04:47.216784+00:00 [queued]>
[2023-06-30T05:20:12.351+0000] {taskinstance.py:1308} INFO - Starting attempt 1 of 6
[2023-06-30T05:20:13.912+0000] {taskinstance.py:1327} INFO - Executing <Task(PythonOperator): check_confidence_task> on 2023-06-30 05:04:47.216784+00:00
[2023-06-30T05:20:13.934+0000] {standard_task_runner.py:57} INFO - Started process 1608 to run task
[2023-06-30T05:20:13.955+0000] {standard_task_runner.py:84} INFO - Running: ['***', 'tasks', 'run', 'order-letter_NER', 'check_confidence_task', 'manual__2023-06-30T05:04:47.216784+00:00', '--job-id', '52', '--raw', '--subdir', 'DAGS_FOLDER/order-letter-extraction.py', '--cfg-path', '/tmp/tmpigdpsr5i']
[2023-06-30T05:20:13.964+0000] {standard_task_runner.py:85} INFO - Job 52: Subtask check_confidence_task
[2023-06-30T05:20:14.291+0000] {task_command.py:410} INFO - Running <TaskInstance: order-letter_NER.check_confidence_task manual__2023-06-30T05:04:47.216784+00:00 [running]> on host f7b244b51c6e
[2023-06-30T05:20:19.578+0000] {taskinstance.py:1545} INFO - Exporting env vars: AIRFLOW_CTX_DAG_OWNER='Abin Jilson' AIRFLOW_CTX_DAG_ID='order-letter_NER' AIRFLOW_CTX_TASK_ID='check_confidence_task' AIRFLOW_CTX_EXECUTION_DATE='2023-06-30T05:04:47.216784+00:00' AIRFLOW_CTX_TRY_NUMBER='1' AIRFLOW_CTX_DAG_RUN_ID='manual__2023-06-30T05:04:47.216784+00:00'
[2023-06-30T05:20:19.583+0000] {taskinstance.py:1824} ERROR - Task failed with exception
Traceback (most recent call last):
  File "/home/airflow/.local/lib/python3.8/site-packages/airflow/operators/python.py", line 181, in execute
    return_value = self.execute_callable()
  File "/home/airflow/.local/lib/python3.8/site-packages/airflow/operators/python.py", line 198, in execute_callable
    return self.python_callable(*self.op_args, **self.op_kwargs)
  File "/opt/airflow/dags/order-letter-extraction.py", line 188, in check_confidence
    if confidence >= 70:
TypeError: '>=' not supported between instances of 'str' and 'int'
[2023-06-30T05:20:19.601+0000] {taskinstance.py:1345} INFO - Marking task as UP_FOR_RETRY. dag_id=order-letter_NER, task_id=check_confidence_task, execution_date=20230630T050447, start_date=20230630T052012, end_date=20230630T052019
[2023-06-30T05:20:22.028+0000] {standard_task_runner.py:104} ERROR - Failed to execute job 52 for task check_confidence_task ('>=' not supported between instances of 'str' and 'int'; 1608)
[2023-06-30T05:20:22.083+0000] {local_task_job_runner.py:225} INFO - Task exited with return code 1
[2023-06-30T05:20:22.152+0000] {taskinstance.py:2653} INFO - 0 downstream tasks scheduled from follow-on schedule check
