[2023-06-29T07:44:42.346+0000] {taskinstance.py:1103} INFO - Dependencies all met for dep_context=non-requeueable deps ti=<TaskInstance: order-letter_NER.read_order_from_mail scheduled__2023-06-28T00:00:00+00:00 [queued]>
[2023-06-29T07:44:42.370+0000] {taskinstance.py:1103} INFO - Dependencies all met for dep_context=requeueable deps ti=<TaskInstance: order-letter_NER.read_order_from_mail scheduled__2023-06-28T00:00:00+00:00 [queued]>
[2023-06-29T07:44:42.371+0000] {taskinstance.py:1308} INFO - Starting attempt 1 of 6
[2023-06-29T07:44:42.403+0000] {taskinstance.py:1327} INFO - Executing <Task(PythonOperator): read_order_from_mail> on 2023-06-28 00:00:00+00:00
[2023-06-29T07:44:42.416+0000] {standard_task_runner.py:57} INFO - Started process 2357 to run task
[2023-06-29T07:44:42.425+0000] {standard_task_runner.py:84} INFO - Running: ['***', 'tasks', 'run', 'order-letter_NER', 'read_order_from_mail', 'scheduled__2023-06-28T00:00:00+00:00', '--job-id', '7', '--raw', '--subdir', 'DAGS_FOLDER/order-letter-extraction.py', '--cfg-path', '/tmp/tmpgxjj45_0']
[2023-06-29T07:44:42.432+0000] {standard_task_runner.py:85} INFO - Job 7: Subtask read_order_from_mail
[2023-06-29T07:44:42.564+0000] {task_command.py:410} INFO - Running <TaskInstance: order-letter_NER.read_order_from_mail scheduled__2023-06-28T00:00:00+00:00 [running]> on host 0eb747d9e0f2
[2023-06-29T07:44:42.750+0000] {taskinstance.py:1545} INFO - Exporting env vars: AIRFLOW_CTX_DAG_OWNER='Abin Jilson' AIRFLOW_CTX_DAG_ID='order-letter_NER' AIRFLOW_CTX_TASK_ID='read_order_from_mail' AIRFLOW_CTX_EXECUTION_DATE='2023-06-28T00:00:00+00:00' AIRFLOW_CTX_TRY_NUMBER='1' AIRFLOW_CTX_DAG_RUN_ID='scheduled__2023-06-28T00:00:00+00:00'
[2023-06-29T08:03:46.262+0000] {logging_mixin.py:149} INFO - An error occurred: [Errno -3] Temporary failure in name resolution
[2023-06-29T10:31:38.017+0000] {local_task_job_runner.py:291} WARNING - State of this instance has been externally set to None. Terminating instance.
[2023-06-29T10:31:38.024+0000] {process_utils.py:131} INFO - Sending Signals.SIGTERM to group 2357. PIDs of all processes in the group: [2357]
[2023-06-29T10:31:38.026+0000] {process_utils.py:86} INFO - Sending the signal Signals.SIGTERM to group 2357
[2023-06-29T10:31:38.027+0000] {taskinstance.py:1517} ERROR - Received SIGTERM. Terminating subprocesses.
[2023-06-29T10:31:38.045+0000] {taskinstance.py:1824} ERROR - Task failed with exception
Traceback (most recent call last):
  File "/home/airflow/.local/lib/python3.8/site-packages/airflow/operators/python.py", line 181, in execute
    return_value = self.execute_callable()
  File "/home/airflow/.local/lib/python3.8/site-packages/airflow/operators/python.py", line 198, in execute_callable
    return self.python_callable(*self.op_args, **self.op_kwargs)
  File "/opt/airflow/dags/order-letter-extraction.py", line 63, in read_order_from_mail
    # Wait for 10 seconds before checking again
  File "/home/airflow/.local/lib/python3.8/site-packages/airflow/models/taskinstance.py", line 1519, in signal_handler
    raise AirflowException("Task received SIGTERM signal")
airflow.exceptions.AirflowException: Task received SIGTERM signal
[2023-06-29T10:31:38.059+0000] {taskinstance.py:1345} INFO - Marking task as UP_FOR_RETRY. dag_id=order-letter_NER, task_id=read_order_from_mail, execution_date=20230628T000000, start_date=20230629T074442, end_date=20230629T103138
[2023-06-29T10:31:38.096+0000] {standard_task_runner.py:104} ERROR - Failed to execute job 7 for task read_order_from_mail (Task received SIGTERM signal; 2357)
[2023-06-29T10:31:38.128+0000] {process_utils.py:79} INFO - Process psutil.Process(pid=2357, status='terminated', exitcode=1, started='07:44:41') (2357) terminated with exit code 1
